<?xml version="1.0"?>
<robot name="modrob1">

	<link name="world"/>

	<gazebo>
		<plugin name="gazebo_ros_control" filename="libgazebo_ros_control.so">
			<robotNamespace>/modrob1</robotNamespace>
			<robotSimType>gazebo_ros_control/DefaultRobotHWSim</robotSimType>
		</plugin>
	</gazebo>

	<link name="part0">
		<visual>
			<origin rpy="0.000000 -0.000000 0.000000" xyz="0.000000 0.000000 0.100000"/>
			<geometry>
				<mesh filename="package://modrob_simulation/stl_files/B_simple.STL"/>
			</geometry>
		</visual>
		<collision>
			<origin rpy="0.000000 -0.000000 0.000000" xyz="0.000000 0.000000 0.050000"/>
			<geometry>
				<box size="0.180000 0.180000 0.100000"/>
			</geometry>
		</collision>
	</link>

	<gazebo reference="part0">
		<material>Gazebo/DarkGrey</material>
	</gazebo>

	<gazebo reference="part0">
		<kp>0.000000</kp>
		<kd>0.000000</kd>
		<mu1>0.000000</mu1>
		<mu2>0.000000</mu2>
	</gazebo>

	<link name="distal_link_of_joint0_NV">
		<inertial>
			<origin rpy="0.000000 0.000000 0.000000" xyz="0.000630 0.000190 -0.009660"/>
			<mass value="0.588000"/>
			<inertia ixx="0.000840" ixy="0.000000" ixz="-0.000011" iyy="0.000833" iyz="-0.000001" izz="0.000732"/>
		</inertial>
	</link>

	<gazebo reference="distal_link_of_joint0_NV">
		<material></material>
	</gazebo>

	<gazebo reference="distal_link_of_joint0_NV">
		<kp>0.000000</kp>
		<kd>0.000000</kd>
		<mu1>0.000000</mu1>
		<mu2>0.000000</mu2>
	</gazebo>

	<link name="proximal_link_of_joint0">
		<inertial>
			<origin rpy="0.000000 0.000000 0.000000" xyz="0.000180 0.000130 0.054300"/>
			<mass value="2.795000"/>
			<inertia ixx="0.014000" ixy="-0.000002" ixz="-0.000003" iyy="0.014000" iyz="0.000005" izz="0.000732"/>
		</inertial>
		<visual>
			<origin rpy="0.000000 -0.000000 0.000000" xyz="0.000000 0.000000 0.135300"/>
			<geometry>
				<mesh filename="package://modrob_simulation/stl_files/MXL_low_poly.STL"/>
			</geometry>
		</visual>
		<collision>
			<origin rpy="0.000000 -0.000000 0.000000" xyz="0.000000 0.000000 0.055150"/>
			<geometry>
				<box size="0.110000 0.110000 0.205480"/>
			</geometry>
		</collision>
	</link>

	<gazebo reference="proximal_link_of_joint0">
		<material>Gazebo/Blue</material>
	</gazebo>

	<gazebo reference="proximal_link_of_joint0">
		<kp>10000.000000</kp>
		<kd>10.000000</kd>
		<mu1>0.200000</mu1>
		<mu2>0.200000</mu2>
	</gazebo>

	<link name="link1">
		<inertial>
			<origin rpy="0.000000 0.000000 0.000000" xyz="0.000200 -0.036560 0.054520"/>
			<mass value="0.581910"/>
			<inertia ixx="0.004886" ixy="0.000007" ixz="-0.000007" iyy="0.003453" iyz="0.001714" izz="0.000000"/>
		</inertial>
		<visual>
			<origin rpy="2.356194 -1.570796 2.356194" xyz="0.000000 -0.065500 0.100900"/>
			<geometry>
				<mesh filename="package://modrob_simulation/stl_files/L_Rasmus_01_90_LL_low_poly.STL"/>
			</geometry>
		</visual>
		<collision>
			<origin rpy="2.356194 -1.570796 2.356194" xyz="0.000000 -0.043660 0.081282"/>
			<geometry>
				<box size="0.162565 0.123596 0.203680"/>
			</geometry>
		</collision>
	</link>

	<gazebo reference="link1">
		<material>Gazebo/DarkGrey</material>
	</gazebo>

	<gazebo reference="link1">
		<kp>0.000000</kp>
		<kd>0.000000</kd>
		<mu1>0.000000</mu1>
		<mu2>0.000000</mu2>
	</gazebo>

	<gazebo reference="link1">
		<sensor name="link1_contact_sensor" type="contact">
			<always_on>1</always_on>
			<plugin name="modrob_contact_plugin" filename="libmodrob_contact_plugin.so">
				<name_space>modrob1</name_space>
			</plugin>
			<contact>
				<collision>distal_link_of_joint0_NV_fixed_joint_lump__link1_collision</collision>
			</contact>
		</sensor>
	</gazebo>

	<link name="distal_link_of_joint1_NV">
		<inertial>
			<origin rpy="0.000000 0.000000 0.000000" xyz="0.000630 0.000190 -0.009660"/>
			<mass value="0.588000"/>
			<inertia ixx="0.000840" ixy="0.000000" ixz="-0.000011" iyy="0.000833" iyz="-0.000001" izz="0.000732"/>
		</inertial>
	</link>

	<gazebo reference="distal_link_of_joint1_NV">
		<material></material>
	</gazebo>

	<gazebo reference="distal_link_of_joint1_NV">
		<kp>0.000000</kp>
		<kd>0.000000</kd>
		<mu1>0.000000</mu1>
		<mu2>0.000000</mu2>
	</gazebo>

	<link name="proximal_link_of_joint1">
		<inertial>
			<origin rpy="0.000000 0.000000 0.000000" xyz="0.000180 0.000130 0.054300"/>
			<mass value="2.795000"/>
			<inertia ixx="0.014000" ixy="0.000002" ixz="0.000003" iyy="0.014000" iyz="-0.000005" izz="0.000732"/>
		</inertial>
		<visual>
			<origin rpy="3.141593 -3.141593 1.570796" xyz="0.000000 0.000000 0.135300"/>
			<geometry>
				<mesh filename="package://modrob_simulation/stl_files/MXL+90_low_poly.STL"/>
			</geometry>
		</visual>
		<collision>
			<origin rpy="3.141593 -3.141593 1.570796" xyz="0.000000 0.000000 0.055150"/>
			<geometry>
				<box size="0.110000 0.110000 0.205480"/>
			</geometry>
		</collision>
	</link>

	<gazebo reference="proximal_link_of_joint1">
		<material>Gazebo/Blue</material>
	</gazebo>

	<gazebo reference="proximal_link_of_joint1">
		<kp>10000.000000</kp>
		<kd>10.000000</kd>
		<mu1>0.200000</mu1>
		<mu2>0.200000</mu2>
	</gazebo>

	<gazebo reference="proximal_link_of_joint1">
		<sensor name="proximal_link_of_joint1_contact_sensor" type="contact">
			<always_on>1</always_on>
			<plugin name="modrob_contact_plugin" filename="libmodrob_contact_plugin.so">
				<name_space>modrob1</name_space>
			</plugin>
			<contact>
				<collision>distal_link_of_joint0_NV_fixed_joint_lump__proximal_link_of_joint1_collision_1</collision>
			</contact>
		</sensor>
	</gazebo>

	<link name="link2">
		<inertial>
			<origin rpy="0.000000 0.000000 0.000000" xyz="0.199960 0.000005 0.044435"/>
			<mass value="1.615669"/>
			<inertia ixx="0.005724" ixy="-0.000002" ixz="-0.014380" iyy="0.098655" iyz="-0.000001" izz="0.000000"/>
		</inertial>
		<visual>
			<origin rpy="-0.000000 -3.141593 0.000000" xyz="-0.000000 0.400000 0.000000"/>
			<geometry>
				<mesh filename="package://modrob_simulation/stl_files/L_360_400_LL_actual.STL"/>
			</geometry>
		</visual>
		<collision>
			<origin rpy="-0.000000 -3.141593 0.000000" xyz="0.000000 0.200000 0.044500"/>
			<geometry>
				<box size="0.111989 0.511780 0.089000"/>
			</geometry>
		</collision>
	</link>

	<gazebo reference="link2">
		<material>Gazebo/DarkGrey</material>
	</gazebo>

	<gazebo reference="link2">
		<kp>0.000000</kp>
		<kd>0.000000</kd>
		<mu1>0.000000</mu1>
		<mu2>0.000000</mu2>
	</gazebo>

	<gazebo reference="link2">
		<sensor name="link2_contact_sensor" type="contact">
			<always_on>1</always_on>
			<plugin name="modrob_contact_plugin" filename="libmodrob_contact_plugin.so">
				<name_space>modrob1</name_space>
			</plugin>
			<contact>
				<collision>distal_link_of_joint1_NV_fixed_joint_lump__link2_collision</collision>
			</contact>
		</sensor>
	</gazebo>

	<link name="distal_link_of_joint2_NV">
		<inertial>
			<origin rpy="0.000000 0.000000 0.000000" xyz="-0.000030 0.000010 -0.015900"/>
			<mass value="0.473600"/>
			<inertia ixx="0.000536" ixy="-0.000000" ixz="-0.000000" iyy="0.000536" iyz="0.000000" izz="0.000564"/>
		</inertial>
	</link>

	<gazebo reference="distal_link_of_joint2_NV">
		<material></material>
	</gazebo>

	<gazebo reference="distal_link_of_joint2_NV">
		<kp>0.000000</kp>
		<kd>0.000000</kd>
		<mu1>0.000000</mu1>
		<mu2>0.000000</mu2>
	</gazebo>

	<link name="proximal_link_of_joint2">
		<inertial>
			<origin rpy="0.000000 0.000000 0.000000" xyz="0.000025 0.001030 0.050400"/>
			<mass value="2.139300"/>
			<inertia ixx="0.009000" ixy="0.000002" ixz="-0.000002" iyy="0.008000" iyz="0.000024" izz="0.000564"/>
		</inertial>
		<visual>
			<origin rpy="0.000000 -0.000000 0.000000" xyz="0.000000 0.000000 0.127600"/>
			<geometry>
				<mesh filename="package://modrob_simulation/stl_files/ML_low_poly.STL"/>
			</geometry>
		</visual>
		<collision>
			<origin rpy="0.000000 -0.000000 0.000000" xyz="0.000000 0.000000 0.051300"/>
			<geometry>
				<box size="0.110000 0.110000 0.197780"/>
			</geometry>
		</collision>
	</link>

	<gazebo reference="proximal_link_of_joint2">
		<material>Gazebo/Blue</material>
	</gazebo>

	<gazebo reference="proximal_link_of_joint2">
		<kp>10000.000000</kp>
		<kd>10.000000</kd>
		<mu1>0.200000</mu1>
		<mu2>0.200000</mu2>
	</gazebo>

	<gazebo reference="proximal_link_of_joint2">
		<sensor name="proximal_link_of_joint2_contact_sensor" type="contact">
			<always_on>1</always_on>
			<plugin name="modrob_contact_plugin" filename="libmodrob_contact_plugin.so">
				<name_space>modrob1</name_space>
			</plugin>
			<contact>
				<collision>distal_link_of_joint1_NV_fixed_joint_lump__proximal_link_of_joint2_collision_1</collision>
			</contact>
		</sensor>
	</gazebo>

	<link name="link3">
		<inertial>
			<origin rpy="0.000000 0.000000 0.000000" xyz="0.060011 0.005268 0.039688"/>
			<mass value="0.578517"/>
			<inertia ixx="0.002063" ixy="-0.000340" ixz="-0.001596" iyy="0.005676" iyz="-0.000134" izz="0.000000"/>
		</inertial>
		<visual>
			<origin rpy="-1.570796 -0.000000 0.000000" xyz="0.114000 0.047000 0.047000"/>
			<geometry>
				<mesh filename="package://modrob_simulation/stl_files/L_90S_compact_LL_actual_low_poly.STL"/>
			</geometry>
		</visual>
		<collision>
			<origin rpy="-1.570796 -0.000000 0.000000" xyz="0.057026 -0.000000 0.047000"/>
			<geometry>
				<box size="0.227949 0.114000 0.114000"/>
			</geometry>
		</collision>
	</link>

	<gazebo reference="link3">
		<material>Gazebo/DarkGrey</material>
	</gazebo>

	<gazebo reference="link3">
		<kp>0.000000</kp>
		<kd>0.000000</kd>
		<mu1>0.000000</mu1>
		<mu2>0.000000</mu2>
	</gazebo>

	<gazebo reference="link3">
		<sensor name="link3_contact_sensor" type="contact">
			<always_on>1</always_on>
			<plugin name="modrob_contact_plugin" filename="libmodrob_contact_plugin.so">
				<name_space>modrob1</name_space>
			</plugin>
			<contact>
				<collision>distal_link_of_joint2_NV_fixed_joint_lump__link3_collision</collision>
			</contact>
		</sensor>
	</gazebo>

	<link name="distal_link_of_joint3_NV">
		<inertial>
			<origin rpy="0.000000 0.000000 0.000000" xyz="-0.000030 0.000010 -0.015900"/>
			<mass value="0.473600"/>
			<inertia ixx="0.000536" ixy="-0.000000" ixz="-0.000000" iyy="0.000536" iyz="0.000000" izz="0.000564"/>
		</inertial>
	</link>

	<gazebo reference="distal_link_of_joint3_NV">
		<material></material>
	</gazebo>

	<gazebo reference="distal_link_of_joint3_NV">
		<kp>0.000000</kp>
		<kd>0.000000</kd>
		<mu1>0.000000</mu1>
		<mu2>0.000000</mu2>
	</gazebo>

	<link name="proximal_link_of_joint3">
		<inertial>
			<origin rpy="0.000000 0.000000 0.000000" xyz="0.000025 0.001030 0.050400"/>
			<mass value="2.139300"/>
			<inertia ixx="0.009000" ixy="0.000002" ixz="-0.000002" iyy="0.008000" iyz="0.000024" izz="0.000564"/>
		</inertial>
		<visual>
			<origin rpy="0.000000 -0.000000 0.000000" xyz="0.000000 0.000000 0.127600"/>
			<geometry>
				<mesh filename="package://modrob_simulation/stl_files/ML_low_poly.STL"/>
			</geometry>
		</visual>
		<collision>
			<origin rpy="0.000000 -0.000000 0.000000" xyz="0.000000 0.000000 0.051300"/>
			<geometry>
				<box size="0.110000 0.110000 0.197780"/>
			</geometry>
		</collision>
	</link>

	<gazebo reference="proximal_link_of_joint3">
		<material>Gazebo/Blue</material>
	</gazebo>

	<gazebo reference="proximal_link_of_joint3">
		<kp>10000.000000</kp>
		<kd>10.000000</kd>
		<mu1>0.200000</mu1>
		<mu2>0.200000</mu2>
	</gazebo>

	<gazebo reference="proximal_link_of_joint3">
		<sensor name="proximal_link_of_joint3_contact_sensor" type="contact">
			<always_on>1</always_on>
			<plugin name="modrob_contact_plugin" filename="libmodrob_contact_plugin.so">
				<name_space>modrob1</name_space>
			</plugin>
			<contact>
				<collision>distal_link_of_joint2_NV_fixed_joint_lump__proximal_link_of_joint3_collision_1</collision>
			</contact>
		</sensor>
	</gazebo>

	<link name="link4">
		<inertial>
			<origin rpy="0.000000 0.000000 0.000000" xyz="0.000006 0.091445 0.125960"/>
			<mass value="1.677416"/>
			<inertia ixx="0.107697" ixy="-0.000001" ixz="-0.000003" iyy="0.091364" iyz="-0.034625" izz="0.000000"/>
		</inertial>
		<visual>
			<origin rpy="1.570796 -0.000000 0.000000" xyz="0.000000 0.065000 0.250000"/>
			<geometry>
				<mesh filename="package://modrob_simulation/stl_files/L_90L_250_LS_actual_low_poly.STL"/>
			</geometry>
		</visual>
		<collision>
			<origin rpy="1.570796 -0.000000 0.000000" xyz="0.000000 0.050000 0.146999"/>
			<geometry>
				<box size="0.111947 0.293998 0.212000"/>
			</geometry>
		</collision>
	</link>

	<gazebo reference="link4">
		<material>Gazebo/DarkGrey</material>
	</gazebo>

	<gazebo reference="link4">
		<kp>0.000000</kp>
		<kd>0.000000</kd>
		<mu1>0.000000</mu1>
		<mu2>0.000000</mu2>
	</gazebo>

	<gazebo reference="link4">
		<sensor name="link4_contact_sensor" type="contact">
			<always_on>1</always_on>
			<plugin name="modrob_contact_plugin" filename="libmodrob_contact_plugin.so">
				<name_space>modrob1</name_space>
			</plugin>
			<contact>
				<collision>distal_link_of_joint3_NV_fixed_joint_lump__link4_collision</collision>
			</contact>
		</sensor>
	</gazebo>

	<link name="distal_link_of_joint4_NV">
		<inertial>
			<origin rpy="0.000000 0.000000 0.000000" xyz="-0.000044 -0.000008 -0.001115"/>
			<mass value="0.289400"/>
			<inertia ixx="0.000178" ixy="-0.000000" ixz="-0.000000" iyy="0.000178" iyz="0.000000" izz="0.000192"/>
		</inertial>
	</link>

	<gazebo reference="distal_link_of_joint4_NV">
		<material></material>
	</gazebo>

	<gazebo reference="distal_link_of_joint4_NV">
		<kp>0.000000</kp>
		<kd>0.000000</kd>
		<mu1>0.000000</mu1>
		<mu2>0.000000</mu2>
	</gazebo>

	<link name="proximal_link_of_joint4">
		<inertial>
			<origin rpy="0.000000 0.000000 0.000000" xyz="0.000610 0.000080 0.047140"/>
			<mass value="1.253380"/>
			<inertia ixx="0.004000" ixy="0.000000" ixz="0.000016" iyy="0.005000" iyz="-0.000000" izz="0.000192"/>
		</inertial>
		<visual>
			<origin rpy="0.000000 -0.000000 0.000000" xyz="0.000000 0.000000 0.119550"/>
			<geometry>
				<mesh filename="package://modrob_simulation/stl_files/MS_low_poly.STL"/>
			</geometry>
		</visual>
		<collision>
			<origin rpy="0.000000 -0.000000 0.000000" xyz="0.000000 0.000000 0.047275"/>
			<geometry>
				<box size="0.086000 0.086000 0.189730"/>
			</geometry>
		</collision>
	</link>

	<gazebo reference="proximal_link_of_joint4">
		<material>Gazebo/Blue</material>
	</gazebo>

	<gazebo reference="proximal_link_of_joint4">
		<kp>10000.000000</kp>
		<kd>10.000000</kd>
		<mu1>0.200000</mu1>
		<mu2>0.200000</mu2>
	</gazebo>

	<gazebo reference="proximal_link_of_joint4">
		<sensor name="proximal_link_of_joint4_contact_sensor" type="contact">
			<always_on>1</always_on>
			<plugin name="modrob_contact_plugin" filename="libmodrob_contact_plugin.so">
				<name_space>modrob1</name_space>
			</plugin>
			<contact>
				<collision>distal_link_of_joint3_NV_fixed_joint_lump__proximal_link_of_joint4_collision_1</collision>
			</contact>
		</sensor>
	</gazebo>

	<link name="link5">
		<inertial>
			<origin rpy="0.000000 0.000000 0.000000" xyz="-0.043600 0.035200 -0.023740"/>
			<mass value="0.337890"/>
			<inertia ixx="0.001553" ixy="0.000777" ixz="-0.000685" iyy="0.001824" iyz="0.000526" izz="0.000000"/>
		</inertial>
		<visual>
			<origin rpy="1.570796 3.141593 1.570796" xyz="-0.060000 0.063000 -0.058000"/>
			<geometry>
				<mesh filename="package://modrob_simulation/stl_files/L_Rasmus_02_90_SS_low_poly.STL"/>
			</geometry>
		</visual>
		<collision>
			<origin rpy="1.570796 3.141593 1.570796" xyz="-0.045752 0.032384 -0.027794"/>
			<geometry>
				<box size="0.160731 0.160389 0.187497"/>
			</geometry>
		</collision>
	</link>

	<gazebo reference="link5">
		<material>Gazebo/DarkGrey</material>
	</gazebo>

	<gazebo reference="link5">
		<kp>0.000000</kp>
		<kd>0.000000</kd>
		<mu1>0.000000</mu1>
		<mu2>0.000000</mu2>
	</gazebo>

	<gazebo reference="link5">
		<sensor name="link5_contact_sensor" type="contact">
			<always_on>1</always_on>
			<plugin name="modrob_contact_plugin" filename="libmodrob_contact_plugin.so">
				<name_space>modrob1</name_space>
			</plugin>
			<contact>
				<collision>distal_link_of_joint4_NV_fixed_joint_lump__link5_collision</collision>
			</contact>
		</sensor>
	</gazebo>

	<link name="tool_dummy">
		<inertial>
			<origin rpy="0.000000 0.000000 0.000000" xyz="0.000610 0.000080 0.047140"/>
			<mass value="0.000000"/>
			<inertia ixx="0.000000" ixy="0.000000" ixz="0.000000" iyy="0.000000" iyz="0.000000" izz="0.000000"/>
		</inertial>
	</link>

	<gazebo reference="tool_dummy">
		<material></material>
	</gazebo>

	<gazebo reference="tool_dummy">
		<kp>0.000000</kp>
		<kd>0.000000</kd>
		<mu1>0.000000</mu1>
		<mu2>0.000000</mu2>
	</gazebo>

	<link name="distal_link_of_joint5_NV">
		<inertial>
			<origin rpy="0.000000 0.000000 0.000000" xyz="-0.000044 -0.000008 -0.001115"/>
			<mass value="0.289400"/>
			<inertia ixx="0.000178" ixy="-0.000000" ixz="-0.000000" iyy="0.000178" iyz="0.000000" izz="0.000192"/>
		</inertial>
	</link>

	<gazebo reference="distal_link_of_joint5_NV">
		<material></material>
	</gazebo>

	<gazebo reference="distal_link_of_joint5_NV">
		<kp>0.000000</kp>
		<kd>0.000000</kd>
		<mu1>0.000000</mu1>
		<mu2>0.000000</mu2>
	</gazebo>

	<link name="proximal_link_of_joint5">
		<inertial>
			<origin rpy="0.000000 0.000000 0.000000" xyz="0.000610 0.000080 0.047140"/>
			<mass value="1.253380"/>
			<inertia ixx="0.004000" ixy="0.000000" ixz="0.000016" iyy="0.005000" iyz="-0.000000" izz="0.000192"/>
		</inertial>
		<visual>
			<origin rpy="0.000000 -0.000000 0.000000" xyz="0.000000 0.000000 0.119550"/>
			<geometry>
				<mesh filename="package://modrob_simulation/stl_files/MS_low_poly.STL"/>
			</geometry>
		</visual>
		<collision>
			<origin rpy="0.000000 -0.000000 0.000000" xyz="0.000000 0.000000 0.047275"/>
			<geometry>
				<box size="0.086000 0.086000 0.189730"/>
			</geometry>
		</collision>
	</link>

	<gazebo reference="proximal_link_of_joint5">
		<material>Gazebo/Blue</material>
	</gazebo>

	<gazebo reference="proximal_link_of_joint5">
		<kp>10000.000000</kp>
		<kd>10.000000</kd>
		<mu1>0.200000</mu1>
		<mu2>0.200000</mu2>
	</gazebo>

	<gazebo reference="proximal_link_of_joint5">
		<sensor name="proximal_link_of_joint5_contact_sensor" type="contact">
			<always_on>1</always_on>
			<plugin name="modrob_contact_plugin" filename="libmodrob_contact_plugin.so">
				<name_space>modrob1</name_space>
			</plugin>
			<contact>
				<collision>distal_link_of_joint4_NV_fixed_joint_lump__proximal_link_of_joint5_collision_1</collision>
			</contact>
		</sensor>
	</gazebo>


	<link name="hand">
		<inertial>
			<origin rpy="0.000000 0.000000 0.000000" xyz="0.000000 0.000000 0.06250"/>
			<mass value="0.184000"/>
			<inertia ixx="0.550000" ixy="-0.000002" ixz="-0.000003" iyy="0.930000" iyz="0.000005" izz="0.550000"/>
		</inertial>
		<visual>
			<origin rpy="0.000000 -0.000000 0.000000" xyz="0.000000 0.000000 0.06250"/>
		<geometry>
				<mesh filename="package://modrob_simulation/stl_files/E_Schimaneck.STL"/>
			</geometry>
		</visual>
		<collision>
			<origin rpy="0.000000 -0.000000 0.000000" xyz="0.002343744 0.000000 0.02165501"/>
			<geometry>
				<box size="0.08531006 0.08485281 0.1616900"/>
			</geometry>
			</collision>
	</link>

	<gazebo reference="hand">
		<material>Gazebo/DarkGrey</material>
	</gazebo>

	<gazebo reference="hand">
		<kp>0.000000</kp>
		<kd>0.000000</kd>
		<mu1>0.000000</mu1>
		<mu2>0.000000</mu2>
	</gazebo>

	<gazebo reference="hand">
		<sensor name="hand_collision_sensor" type="contact">
			<always_on>true</always_on>
			<plugin name="modrob_contact_plugin" filename="libmodrob_contact_plugin.so">
				<name_space>modrob1</name_space>
			</plugin>
			<contact>
				<collision>distal_link_of_joint5_NV_fixed_joint_lump__hand_collision</collision>
			</contact>
		</sensor>
	</gazebo>

	<link name="finger1">
		<inertial>
			<origin rpy="0.00000 0.000000 0.0" xyz="0.0 -0.000 0.001500"/>
			<mass value="0.006944"/>
			<inertia ixx="0.000004629" ixy="0.000000486" ixz="0.000000972" iyy="0.000004157" iyz="0.000001389" izz="0.00000138"/>
		</inertial>
		<visual>
			<origin rpy="0.000000 0.000000 0.0" xyz="0.0 -0.000 0.001500"/>
			<geometry>
				<mesh filename="package://modrob_simulation/stl_files/finger_Birne_Gimatic_m.STL"/>
			</geometry>
		</visual>
	</link>

	<gazebo reference="finger1">
		<material>Gazebo/Blue</material>
	</gazebo>

	<gazebo reference="finger1">
		<kp>110.000000</kp>
		<kd>10.000000</kd>
		<mu1>100.00</mu1>
		<mu2>100.00</mu2>
	</gazebo>

	<link name="finger2">
		<inertial>
			<origin rpy="0.00000 0.000000 0.0" xyz="0.000 0.00 0.001500"/>
			<mass value="0.006944"/>
			<inertia ixx="0.000004629" ixy="0.000000486" ixz="0.000000972" iyy="0.000004157" iyz="0.000001389" izz="0.00000138"/>
		</inertial>
		<visual>
			<origin rpy="0.000000 0.000000 0.0" xyz="0.000 0.00 0.001500"/>
			<geometry>
				<mesh filename="package://modrob_simulation/stl_files/finger_Birne_Gimatic_m.STL"/>
			</geometry>
		</visual>
	</link>

	<gazebo reference="finger2">
		<material>Gazebo/Blue</material>
	</gazebo>

	<gazebo reference="finger2">
		<kp>110.000000</kp>
		<kd>10.000000</kd>
		<mu1>100.00</mu1>
		<mu2>100.00</mu2>
	</gazebo>

	<joint name="fixed" type="fixed">
		<parent link="world"/>
		<child link="part0"/>
	</joint>
	<joint name="part0_joint0" type="fixed">
		<origin xyz="0.000000 0.000000 0.100000" rpy="0.000000 -0.000000 0.000000"/>
		<parent link="part0"/>
		<child link="proximal_link_of_joint0"/>
		<axis xyz="0.000000 0.000000 0.000000"/>
		<dynamics damping="0.000000" friction="0.000000"/>
	</joint>

	<joint name="joint0_link1" type="fixed">
		<origin xyz="0.000000 0.000000 0.135300" rpy="0.000000 -0.000000 0.000000"/>
		<parent link="distal_link_of_joint0_NV"/>
		<child link="link1"/>
		<axis xyz="0.000000 0.000000 0.000000"/>
		<dynamics damping="0.000000" friction="0.000000"/>
	</joint>

	<joint name="joint0" type="revolute">
		<origin xyz="0.000000 0.000000 0.000000" rpy="0.000000 -0.000000 0.000000"/>
		<parent link="proximal_link_of_joint0"/>
		<child link="distal_link_of_joint0_NV"/>
		<axis xyz="0.000000 0.000000 1.000000"/>
		<dynamics damping="51.459999" friction="36.560001"/>
		<limit effort="205.919998" velocity="1.890000" lower="-3.141593" upper="3.141593"/>
		<sensor name="force_torque_joint0" type="force_torque">
			<update_rate>100</update_rate>
		</sensor>
	</joint>

	<transmission name="trans0">
		<type>transmission_interface/SimpleTransmission</type>
		<joint name="joint0">
			<hardwareInterface>hardware_interface/EffortJointInterface</hardwareInterface>
		</joint>
		<actuator name="motor0">
			<hardwareInterface>hardware_interface/EffortJointInterface</hardwareInterface>
			<mechanicalReduction>160.000000</mechanicalReduction>
		</actuator>
	</transmission>

	<joint name="link1_joint1" type="fixed">
		<origin xyz="0.000000 -0.065500 0.100900" rpy="2.356194 -1.570796 2.356194"/>
		<parent link="link1"/>
		<child link="proximal_link_of_joint1"/>
		<axis xyz="0.000000 0.000000 0.000000"/>
		<dynamics damping="0.000000" friction="0.000000"/>
	</joint>

	<joint name="joint1_link2" type="fixed">
		<origin xyz="0.000000 0.000000 0.135300" rpy="3.141593 -3.141593 1.570796"/>
		<parent link="distal_link_of_joint1_NV"/>
		<child link="link2"/>
		<axis xyz="0.000000 0.000000 0.000000"/>
		<dynamics damping="0.000000" friction="0.000000"/>
	</joint>

	<joint name="joint1" type="revolute">
		<origin xyz="0.000000 0.000000 0.000000" rpy="0.000000 -0.000000 0.000000"/>
		<parent link="proximal_link_of_joint1"/>
		<child link="distal_link_of_joint1_NV"/>
		<axis xyz="0.000000 0.000000 1.000000"/>
		<dynamics damping="51.459999" friction="36.560001"/>
		<limit effort="205.919998" velocity="0.800000" lower="-3.141593" upper="3.141593"/>
		<sensor name="force_torque_joint1" type="force_torque">
			<update_rate>100</update_rate>
		</sensor>
	</joint>

	<transmission name="trans1">
		<type>transmission_interface/SimpleTransmission</type>
		<joint name="joint1">
			<hardwareInterface>hardware_interface/EffortJointInterface</hardwareInterface>
		</joint>
		<actuator name="motor1">
			<hardwareInterface>hardware_interface/EffortJointInterface</hardwareInterface>
			<mechanicalReduction>160.000000</mechanicalReduction>
		</actuator>
	</transmission>

	<joint name="link2_joint2" type="fixed">
		<origin xyz="-0.000000 0.400000 0.000000" rpy="-0.000000 -3.141593 0.000000"/>
		<parent link="link2"/>
		<child link="proximal_link_of_joint2"/>
		<axis xyz="0.000000 0.000000 0.000000"/>
		<dynamics damping="0.000000" friction="0.000000"/>
	</joint>

	<joint name="joint2_link3" type="fixed">
		<origin xyz="0.000000 0.000000 0.127600" rpy="0.000000 -0.000000 0.000000"/>
		<parent link="distal_link_of_joint2_NV"/>
		<child link="link3"/>
		<axis xyz="0.000000 0.000000 0.000000"/>
		<dynamics damping="0.000000" friction="0.000000"/>
	</joint>

	<joint name="joint2" type="revolute">
		<origin xyz="0.000000 0.000000 0.000000" rpy="0.000000 -0.000000 0.000000"/>
		<parent link="proximal_link_of_joint2"/>
		<child link="distal_link_of_joint2_NV"/>
		<axis xyz="0.000000 0.000000 1.000000"/>
		<dynamics damping="12.590000" friction="18.400000"/>
		<limit effort="106.559998" velocity="2.350000" lower="-3.141593" upper="3.141593"/>
		<sensor name="force_torque_joint2" type="force_torque">
			<update_rate>100</update_rate>
		</sensor>
	</joint>

	<transmission name="trans2">
		<type>transmission_interface/SimpleTransmission</type>
		<joint name="joint2">
			<hardwareInterface>hardware_interface/EffortJointInterface</hardwareInterface>
		</joint>
		<actuator name="motor2">
			<hardwareInterface>hardware_interface/EffortJointInterface</hardwareInterface>
			<mechanicalReduction>160.000000</mechanicalReduction>
		</actuator>
	</transmission>

	<joint name="link3_joint3" type="fixed">
		<origin xyz="0.114000 0.047000 0.047000" rpy="-1.570796 -0.000000 0.000000"/>
		<parent link="link3"/>
		<child link="proximal_link_of_joint3"/>
		<axis xyz="0.000000 0.000000 0.000000"/>
		<dynamics damping="0.000000" friction="0.000000"/>
	</joint>

	<joint name="joint3_link4" type="fixed">
		<origin xyz="0.000000 0.000000 0.127600" rpy="0.000000 -0.000000 0.000000"/>
		<parent link="distal_link_of_joint3_NV"/>
		<child link="link4"/>
		<axis xyz="0.000000 0.000000 0.000000"/>
		<dynamics damping="0.000000" friction="0.000000"/>
	</joint>

	<joint name="joint3" type="revolute">
		<origin xyz="0.000000 0.000000 0.000000" rpy="0.000000 -0.000000 0.000000"/>
		<parent link="proximal_link_of_joint3"/>
		<child link="distal_link_of_joint3_NV"/>
		<axis xyz="0.000000 0.000000 1.000000"/>
		<dynamics damping="12.590000" friction="18.400000"/>
		<limit effort="106.559998" velocity="2.350000" lower="-3.141593" upper="3.141593"/>
		<sensor name="force_torque_joint3" type="force_torque">
			<update_rate>100</update_rate>
		</sensor>
	</joint>

	<transmission name="trans3">
		<type>transmission_interface/SimpleTransmission</type>
		<joint name="joint3">
			<hardwareInterface>hardware_interface/EffortJointInterface</hardwareInterface>
		</joint>
		<actuator name="motor3">
			<hardwareInterface>hardware_interface/EffortJointInterface</hardwareInterface>
			<mechanicalReduction>160.000000</mechanicalReduction>
		</actuator>
	</transmission>

	<joint name="link4_joint4" type="fixed">
		<origin xyz="0.000000 0.065000 0.250000" rpy="1.570796 -0.000000 0.000000"/>
		<parent link="link4"/>
		<child link="proximal_link_of_joint4"/>
		<axis xyz="0.000000 0.000000 0.000000"/>
		<dynamics damping="0.000000" friction="0.000000"/>
	</joint>

	<joint name="joint4_link5" type="fixed">
		<origin xyz="0.000000 0.000000 0.119550" rpy="0.000000 -0.000000 0.000000"/>
		<parent link="distal_link_of_joint4_NV"/>
		<child link="link5"/>
		<axis xyz="0.000000 0.000000 0.000000"/>
		<dynamics damping="0.000000" friction="0.000000"/>
	</joint>

	<joint name="joint4" type="revolute">
		<origin xyz="0.000000 0.000000 0.000000" rpy="0.000000 -0.000000 0.000000"/>
		<parent link="proximal_link_of_joint4"/>
		<child link="distal_link_of_joint4_NV"/>
		<axis xyz="0.000000 0.000000 1.000000"/>
		<dynamics damping="13.170000" friction="6.019000"/>
		<limit effort="54.000000" velocity="3.050000" lower="-3.141593" upper="3.141593"/>
		<sensor name="force_torque_joint4" type="force_torque">
			<update_rate>100</update_rate>
		</sensor>
	</joint>

	<transmission name="trans4">
		<type>transmission_interface/SimpleTransmission</type>
		<joint name="joint4">
			<hardwareInterface>hardware_interface/EffortJointInterface</hardwareInterface>
		</joint>
		<actuator name="motor4">
			<hardwareInterface>hardware_interface/EffortJointInterface</hardwareInterface>
			<mechanicalReduction>120.000000</mechanicalReduction>
		</actuator>
	</transmission>

	<joint name="link5_joint5" type="fixed">
		<origin xyz="-0.060000 0.063000 -0.058000" rpy="1.570796 3.141593 1.570796"/>
		<parent link="link5"/>
		<child link="proximal_link_of_joint5"/>
		<axis xyz="0.000000 0.000000 0.000000"/>
		<dynamics damping="0.000000" friction="0.000000"/>
	</joint>

	<joint name="joint5_tool_dummy" type="fixed">
		<origin xyz="0.000000 0.000000 0.119550" rpy="0.000000 -0.000000 0.000000"/>
		<parent link="distal_link_of_joint5_NV"/>
		<child link="tool_dummy"/>
		<axis xyz="0.000000 0.000000 0.000000"/>
		<dynamics damping="0.000000" friction="0.000000"/>
	</joint>

	<joint name="joint5" type="revolute">
		<origin xyz="0.000000 0.000000 0.000000" rpy="0.000000 -0.000000 0.000000"/>
		<parent link="proximal_link_of_joint5"/>
		<child link="distal_link_of_joint5_NV"/>
		<axis xyz="0.000000 0.000000 1.000000"/>
		<dynamics damping="13.170000" friction="6.019000"/>
		<limit effort="54.000000" velocity="3.050000" lower="-3.141593" upper="3.141593"/>
		<sensor name="force_torque_joint5" type="force_torque">
			<update_rate>100</update_rate>
		</sensor>
	</joint>

	<transmission name="trans5">
		<type>transmission_interface/SimpleTransmission</type>
		<joint name="joint5">
			<hardwareInterface>hardware_interface/EffortJointInterface</hardwareInterface>
		</joint>
		<actuator name="motor5">
			<hardwareInterface>hardware_interface/EffortJointInterface</hardwareInterface>
			<mechanicalReduction>120.000000</mechanicalReduction>
		</actuator>
	</transmission>


	<joint name="fixed_gripper_to_arm_link" type="fixed">
		<origin rpy="0.000000 0.000000 0.000000" xyz="0.000000 0.000000 0.059775"/>
		<parent link="tool_dummy"/>
		<child link="hand"/>
	</joint>

	<joint name="hand_to_finger1" type="prismatic">
		<origin rpy="0.000000 0.000000 +1.570796327" xyz="0.00700 -0.03200 0.06200"/>
		<parent link="hand"/>
		<child link="finger1"/>
		<dynamics damping="12.590000" friction="0.400000"/>
		<limit effort="3.0" lower="-0.0" upper="0.0100" velocity="0.5"/> <!-- was 0.38 and 0.0 -->
	</joint>

	<joint name="hand_to_finger2" type="prismatic">
		<origin rpy="0.000000 0.000000 -1.570796327" xyz="-0.00700 0.0620 0.06200"/>
		<parent link="hand"/>
		<child link="finger2"/>
		<dynamics damping="12.590000" friction="0.400000"/>
		<limit effort="3.0" lower="0.03" upper="0.04" velocity="0.5"/>
	</joint>

	<transmission name="trans_hand_to_finger1">
		<type>transmission_interface/SimpleTransmission</type>
		<joint name="hand_to_finger1">
			<hardwareInterface>hardware_interface/EffortJointInterface</hardwareInterface>
		</joint>
		<actuator name="motor_hand_to_finger1">
			<hardwareInterface>hardware_interface/EffortJointInterface</hardwareInterface>
			<mechanicalReduction>160</mechanicalReduction>
		</actuator>
	</transmission>

	<transmission name="trans_hand_to_finger2">
		<type>transmission_interface/SimpleTransmission</type>
		<joint name="hand_to_finger2">
			<hardwareInterface>hardware_interface/EffortJointInterface</hardwareInterface>
		</joint>
		<actuator name="motor_hand_to_finger2">
			<hardwareInterface>hardware_interface/EffortJointInterface</hardwareInterface>
			<mechanicalReduction>160</mechanicalReduction>
		</actuator>
	</transmission>

</robot>
